ERROR - 2025-09-19 04:09:39 --> Error connecting to the database: mysqli_sql_exception: No connection could be made because the target machine actively refused it in C:\xampp\htdocs\sidodik\system\Database\MySQLi\Connection.php:201
Stack trace:
#0 C:\xampp\htdocs\sidodik\system\Database\MySQLi\Connection.php(201): mysqli->real_connect('localhost', 'root', Object(SensitiveParameterValue), 'sidodik', 3306, '', 0)
#1 C:\xampp\htdocs\sidodik\system\Database\BaseConnection.php(419): CodeIgniter\Database\MySQLi\Connection->connect(false)
#2 C:\xampp\htdocs\sidodik\system\Database\BaseConnection.php(614): CodeIgniter\Database\BaseConnection->initialize()
#3 C:\xampp\htdocs\sidodik\system\Database\BaseBuilder.php(1649): CodeIgniter\Database\BaseConnection->query('SELECT *\nFROM `...', Array, false)
#4 C:\xampp\htdocs\sidodik\system\Model.php(330): CodeIgniter\Database\BaseBuilder->get()
#5 C:\xampp\htdocs\sidodik\system\BaseModel.php(715): CodeIgniter\Model->doFirst()
#6 C:\xampp\htdocs\sidodik\app\Models\UserModel.php(65): CodeIgniter\BaseModel->first()
#7 C:\xampp\htdocs\sidodik\app\Controllers\Auth.php(189): App\Models\UserModel->getUserByNIP('198501012010032...')
#8 C:\xampp\htdocs\sidodik\system\CodeIgniter.php(933): App\Controllers\Auth->processLogin()
#9 C:\xampp\htdocs\sidodik\system\CodeIgniter.php(507): CodeIgniter\CodeIgniter->runController(Object(App\Controllers\Auth))
#10 C:\xampp\htdocs\sidodik\system\CodeIgniter.php(354): CodeIgniter\CodeIgniter->handleRequest(NULL, Object(Config\Cache), false)
#11 C:\xampp\htdocs\sidodik\system\Boot.php(363): CodeIgniter\CodeIgniter->run()
#12 C:\xampp\htdocs\sidodik\system\Boot.php(68): CodeIgniter\Boot::runCodeIgniter(Object(CodeIgniter\CodeIgniter))
#13 C:\xampp\htdocs\sidodik\public\index.php(59): CodeIgniter\Boot::bootWeb(Object(Config\Paths))
#14 C:\xampp\htdocs\sidodik\system\rewrite.php(44): require_once('C:\\xampp\\htdocs...')
#15 {main}

Next CodeIgniter\Database\Exceptions\DatabaseException: No connection could be made because the target machine actively refused it in C:\xampp\htdocs\sidodik\system\Database\MySQLi\Connection.php:246
Stack trace:
#0 C:\xampp\htdocs\sidodik\system\Database\BaseConnection.php(419): CodeIgniter\Database\MySQLi\Connection->connect(false)
#1 C:\xampp\htdocs\sidodik\system\Database\BaseConnection.php(614): CodeIgniter\Database\BaseConnection->initialize()
#2 C:\xampp\htdocs\sidodik\system\Database\BaseBuilder.php(1649): CodeIgniter\Database\BaseConnection->query('SELECT *\nFROM `...', Array, false)
#3 C:\xampp\htdocs\sidodik\system\Model.php(330): CodeIgniter\Database\BaseBuilder->get()
#4 C:\xampp\htdocs\sidodik\system\BaseModel.php(715): CodeIgniter\Model->doFirst()
#5 C:\xampp\htdocs\sidodik\app\Models\UserModel.php(65): CodeIgniter\BaseModel->first()
#6 C:\xampp\htdocs\sidodik\app\Controllers\Auth.php(189): App\Models\UserModel->getUserByNIP('198501012010032...')
#7 C:\xampp\htdocs\sidodik\system\CodeIgniter.php(933): App\Controllers\Auth->processLogin()
#8 C:\xampp\htdocs\sidodik\system\CodeIgniter.php(507): CodeIgniter\CodeIgniter->runController(Object(App\Controllers\Auth))
#9 C:\xampp\htdocs\sidodik\system\CodeIgniter.php(354): CodeIgniter\CodeIgniter->handleRequest(NULL, Object(Config\Cache), false)
#10 C:\xampp\htdocs\sidodik\system\Boot.php(363): CodeIgniter\CodeIgniter->run()
#11 C:\xampp\htdocs\sidodik\system\Boot.php(68): CodeIgniter\Boot::runCodeIgniter(Object(CodeIgniter\CodeIgniter))
#12 C:\xampp\htdocs\sidodik\public\index.php(59): CodeIgniter\Boot::bootWeb(Object(Config\Paths))
#13 C:\xampp\htdocs\sidodik\system\rewrite.php(44): require_once('C:\\xampp\\htdocs...')
#14 {main}
CRITICAL - 2025-09-19 04:09:39 --> CodeIgniter\Database\Exceptions\DatabaseException: Unable to connect to the database.
Main connection [MySQLi]: No connection could be made because the target machine actively refused it
[Method: POST, Route: auth/processLogin]
in SYSTEMPATH\Database\BaseConnection.php on line 465.
 1 SYSTEMPATH\Database\BaseConnection.php(614): CodeIgniter\Database\BaseConnection->initialize()
 2 SYSTEMPATH\Database\BaseBuilder.php(1649): CodeIgniter\Database\BaseConnection->query('SELECT *
FROM `users`
WHERE `nip` = :nip:
 LIMIT 1', [...], false)
 3 SYSTEMPATH\Model.php(330): CodeIgniter\Database\BaseBuilder->get()
 4 SYSTEMPATH\BaseModel.php(715): CodeIgniter\Model->doFirst()
 5 APPPATH\Models\UserModel.php(65): CodeIgniter\BaseModel->first()
 6 APPPATH\Controllers\Auth.php(189): App\Models\UserModel->getUserByNIP('198501012010032076')
 7 SYSTEMPATH\CodeIgniter.php(933): App\Controllers\Auth->processLogin()
 8 SYSTEMPATH\CodeIgniter.php(507): CodeIgniter\CodeIgniter->runController(Object(App\Controllers\Auth))
 9 SYSTEMPATH\CodeIgniter.php(354): CodeIgniter\CodeIgniter->handleRequest(null, Object(Config\Cache), false)
10 SYSTEMPATH\Boot.php(363): CodeIgniter\CodeIgniter->run()
11 SYSTEMPATH\Boot.php(68): CodeIgniter\Boot::runCodeIgniter(Object(CodeIgniter\CodeIgniter))
12 FCPATH\index.php(59): CodeIgniter\Boot::bootWeb(Object(Config\Paths))
13 SYSTEMPATH\rewrite.php(44): require_once('C:\\xampp\\htdocs\\sidodik\\public\\index.php')
ERROR - 2025-09-19 04:09:52 --> mysqli_sql_exception: Unknown column 'updated_at' in 'field list' in C:\xampp\htdocs\sidodik\system\Database\MySQLi\Connection.php:327
Stack trace:
#0 C:\xampp\htdocs\sidodik\system\Database\MySQLi\Connection.php(327): mysqli->query('INSERT INTO `lo...', 0)
#1 C:\xampp\htdocs\sidodik\system\Database\BaseConnection.php(729): CodeIgniter\Database\MySQLi\Connection->execute('INSERT INTO `lo...')
#2 C:\xampp\htdocs\sidodik\system\Database\BaseConnection.php(646): CodeIgniter\Database\BaseConnection->simpleQuery('INSERT INTO `lo...')
#3 C:\xampp\htdocs\sidodik\system\Database\BaseBuilder.php(2345): CodeIgniter\Database\BaseConnection->query('INSERT INTO `lo...', Array, false)
#4 C:\xampp\htdocs\sidodik\system\Model.php(394): CodeIgniter\Database\BaseBuilder->insert()
#5 C:\xampp\htdocs\sidodik\system\BaseModel.php(838): CodeIgniter\Model->doInsert(Array)
#6 C:\xampp\htdocs\sidodik\system\Model.php(797): CodeIgniter\BaseModel->insert(Array, true)
#7 C:\xampp\htdocs\sidodik\app\Models\LogActivityModel.php(37): CodeIgniter\Model->insert(Array)
#8 C:\xampp\htdocs\sidodik\app\Controllers\Auth.php(239): App\Models\LogActivityModel->logActivity('33', 'login', NULL, '::1', Object(CodeIgniter\HTTP\UserAgent))
#9 C:\xampp\htdocs\sidodik\system\CodeIgniter.php(933): App\Controllers\Auth->processLogin()
#10 C:\xampp\htdocs\sidodik\system\CodeIgniter.php(507): CodeIgniter\CodeIgniter->runController(Object(App\Controllers\Auth))
#11 C:\xampp\htdocs\sidodik\system\CodeIgniter.php(354): CodeIgniter\CodeIgniter->handleRequest(NULL, Object(Config\Cache), false)
#12 C:\xampp\htdocs\sidodik\system\Boot.php(363): CodeIgniter\CodeIgniter->run()
#13 C:\xampp\htdocs\sidodik\system\Boot.php(68): CodeIgniter\Boot::runCodeIgniter(Object(CodeIgniter\CodeIgniter))
#14 C:\xampp\htdocs\sidodik\public\index.php(59): CodeIgniter\Boot::bootWeb(Object(Config\Paths))
#15 C:\xampp\htdocs\sidodik\system\rewrite.php(44): require_once('C:\\xampp\\htdocs...')
#16 {main}
ERROR - 2025-09-19 04:09:52 --> Gagal log activity: Unknown column 'updated_at' in 'field list'
ERROR - 2025-09-19 04:10:40 --> mysqli_sql_exception: Unknown column 'updated_at' in 'field list' in C:\xampp\htdocs\sidodik\system\Database\MySQLi\Connection.php:327
Stack trace:
#0 C:\xampp\htdocs\sidodik\system\Database\MySQLi\Connection.php(327): mysqli->query('INSERT INTO `lo...', 0)
#1 C:\xampp\htdocs\sidodik\system\Database\BaseConnection.php(729): CodeIgniter\Database\MySQLi\Connection->execute('INSERT INTO `lo...')
#2 C:\xampp\htdocs\sidodik\system\Database\BaseConnection.php(646): CodeIgniter\Database\BaseConnection->simpleQuery('INSERT INTO `lo...')
#3 C:\xampp\htdocs\sidodik\system\Database\BaseBuilder.php(2345): CodeIgniter\Database\BaseConnection->query('INSERT INTO `lo...', Array, false)
#4 C:\xampp\htdocs\sidodik\system\Model.php(394): CodeIgniter\Database\BaseBuilder->insert()
#5 C:\xampp\htdocs\sidodik\system\BaseModel.php(838): CodeIgniter\Model->doInsert(Array)
#6 C:\xampp\htdocs\sidodik\system\Model.php(797): CodeIgniter\BaseModel->insert(Array, true)
#7 C:\xampp\htdocs\sidodik\app\Models\LogActivityModel.php(37): CodeIgniter\Model->insert(Array)
#8 C:\xampp\htdocs\sidodik\app\Controllers\Auth.php(265): App\Models\LogActivityModel->logActivity('33', 'logout', NULL, '::1', Object(CodeIgniter\HTTP\UserAgent))
#9 C:\xampp\htdocs\sidodik\system\CodeIgniter.php(933): App\Controllers\Auth->logout()
#10 C:\xampp\htdocs\sidodik\system\CodeIgniter.php(507): CodeIgniter\CodeIgniter->runController(Object(App\Controllers\Auth))
#11 C:\xampp\htdocs\sidodik\system\CodeIgniter.php(354): CodeIgniter\CodeIgniter->handleRequest(NULL, Object(Config\Cache), false)
#12 C:\xampp\htdocs\sidodik\system\Boot.php(363): CodeIgniter\CodeIgniter->run()
#13 C:\xampp\htdocs\sidodik\system\Boot.php(68): CodeIgniter\Boot::runCodeIgniter(Object(CodeIgniter\CodeIgniter))
#14 C:\xampp\htdocs\sidodik\public\index.php(59): CodeIgniter\Boot::bootWeb(Object(Config\Paths))
#15 C:\xampp\htdocs\sidodik\system\rewrite.php(44): require_once('C:\\xampp\\htdocs...')
#16 {main}
ERROR - 2025-09-19 04:10:40 --> Gagal log logout: Unknown column 'updated_at' in 'field list'
ERROR - 2025-09-19 04:10:50 --> mysqli_sql_exception: Unknown column 'updated_at' in 'field list' in C:\xampp\htdocs\sidodik\system\Database\MySQLi\Connection.php:327
Stack trace:
#0 C:\xampp\htdocs\sidodik\system\Database\MySQLi\Connection.php(327): mysqli->query('INSERT INTO `lo...', 0)
#1 C:\xampp\htdocs\sidodik\system\Database\BaseConnection.php(729): CodeIgniter\Database\MySQLi\Connection->execute('INSERT INTO `lo...')
#2 C:\xampp\htdocs\sidodik\system\Database\BaseConnection.php(646): CodeIgniter\Database\BaseConnection->simpleQuery('INSERT INTO `lo...')
#3 C:\xampp\htdocs\sidodik\system\Database\BaseBuilder.php(2345): CodeIgniter\Database\BaseConnection->query('INSERT INTO `lo...', Array, false)
#4 C:\xampp\htdocs\sidodik\system\Model.php(394): CodeIgniter\Database\BaseBuilder->insert()
#5 C:\xampp\htdocs\sidodik\system\BaseModel.php(838): CodeIgniter\Model->doInsert(Array)
#6 C:\xampp\htdocs\sidodik\system\Model.php(797): CodeIgniter\BaseModel->insert(Array, true)
#7 C:\xampp\htdocs\sidodik\app\Models\LogActivityModel.php(37): CodeIgniter\Model->insert(Array)
#8 C:\xampp\htdocs\sidodik\app\Controllers\Auth.php(239): App\Models\LogActivityModel->logActivity('1', 'login', NULL, '::1', Object(CodeIgniter\HTTP\UserAgent))
#9 C:\xampp\htdocs\sidodik\system\CodeIgniter.php(933): App\Controllers\Auth->processLogin()
#10 C:\xampp\htdocs\sidodik\system\CodeIgniter.php(507): CodeIgniter\CodeIgniter->runController(Object(App\Controllers\Auth))
#11 C:\xampp\htdocs\sidodik\system\CodeIgniter.php(354): CodeIgniter\CodeIgniter->handleRequest(NULL, Object(Config\Cache), false)
#12 C:\xampp\htdocs\sidodik\system\Boot.php(363): CodeIgniter\CodeIgniter->run()
#13 C:\xampp\htdocs\sidodik\system\Boot.php(68): CodeIgniter\Boot::runCodeIgniter(Object(CodeIgniter\CodeIgniter))
#14 C:\xampp\htdocs\sidodik\public\index.php(59): CodeIgniter\Boot::bootWeb(Object(Config\Paths))
#15 C:\xampp\htdocs\sidodik\system\rewrite.php(44): require_once('C:\\xampp\\htdocs...')
#16 {main}
ERROR - 2025-09-19 04:10:50 --> Gagal log activity: Unknown column 'updated_at' in 'field list'
ERROR - 2025-09-19 04:12:28 --> mysqli_sql_exception: Unknown column 'updated_at' in 'field list' in C:\xampp\htdocs\sidodik\system\Database\MySQLi\Connection.php:327
Stack trace:
#0 C:\xampp\htdocs\sidodik\system\Database\MySQLi\Connection.php(327): mysqli->query('INSERT INTO `lo...', 0)
#1 C:\xampp\htdocs\sidodik\system\Database\BaseConnection.php(729): CodeIgniter\Database\MySQLi\Connection->execute('INSERT INTO `lo...')
#2 C:\xampp\htdocs\sidodik\system\Database\BaseConnection.php(646): CodeIgniter\Database\BaseConnection->simpleQuery('INSERT INTO `lo...')
#3 C:\xampp\htdocs\sidodik\system\Database\BaseBuilder.php(2345): CodeIgniter\Database\BaseConnection->query('INSERT INTO `lo...', Array, false)
#4 C:\xampp\htdocs\sidodik\system\Model.php(394): CodeIgniter\Database\BaseBuilder->insert()
#5 C:\xampp\htdocs\sidodik\system\BaseModel.php(838): CodeIgniter\Model->doInsert(Array)
#6 C:\xampp\htdocs\sidodik\system\Model.php(797): CodeIgniter\BaseModel->insert(Array, true)
#7 C:\xampp\htdocs\sidodik\app\Models\LogActivityModel.php(37): CodeIgniter\Model->insert(Array)
#8 C:\xampp\htdocs\sidodik\app\Controllers\Auth.php(265): App\Models\LogActivityModel->logActivity('1', 'logout', NULL, '::1', Object(CodeIgniter\HTTP\UserAgent))
#9 C:\xampp\htdocs\sidodik\system\CodeIgniter.php(933): App\Controllers\Auth->logout()
#10 C:\xampp\htdocs\sidodik\system\CodeIgniter.php(507): CodeIgniter\CodeIgniter->runController(Object(App\Controllers\Auth))
#11 C:\xampp\htdocs\sidodik\system\CodeIgniter.php(354): CodeIgniter\CodeIgniter->handleRequest(NULL, Object(Config\Cache), false)
#12 C:\xampp\htdocs\sidodik\system\Boot.php(363): CodeIgniter\CodeIgniter->run()
#13 C:\xampp\htdocs\sidodik\system\Boot.php(68): CodeIgniter\Boot::runCodeIgniter(Object(CodeIgniter\CodeIgniter))
#14 C:\xampp\htdocs\sidodik\public\index.php(59): CodeIgniter\Boot::bootWeb(Object(Config\Paths))
#15 C:\xampp\htdocs\sidodik\system\rewrite.php(44): require_once('C:\\xampp\\htdocs...')
#16 {main}
ERROR - 2025-09-19 04:12:28 --> Gagal log logout: Unknown column 'updated_at' in 'field list'
